2022-09-11 10:48:28,012 ERROR Internal Server Error: /news/105 /Users/sergo/Documents/WEB/WebLessons/News_Portal/venv/lib/python3.10/site-packages/django/utils/log.py (<class 'IndexError'>, IndexError('string index out of range'), <traceback object at 0x110b90340>)
Traceback (most recent call last):
  File "/Users/sergo/Documents/WEB/WebLessons/News_Portal/venv/lib/python3.10/site-packages/django/core/handlers/exception.py", line 55, in inner
    response = get_response(request)
  File "/Users/sergo/Documents/WEB/WebLessons/News_Portal/venv/lib/python3.10/site-packages/django/core/handlers/base.py", line 220, in _get_response
    response = response.render()
  File "/Users/sergo/Documents/WEB/WebLessons/News_Portal/venv/lib/python3.10/site-packages/django/template/response.py", line 114, in render
    self.content = self.rendered_content
  File "/Users/sergo/Documents/WEB/WebLessons/News_Portal/venv/lib/python3.10/site-packages/django/template/response.py", line 92, in rendered_content
    return template.render(context, self._request)
  File "/Users/sergo/Documents/WEB/WebLessons/News_Portal/venv/lib/python3.10/site-packages/django/template/backends/django.py", line 62, in render
    return self.template.render(context)
  File "/Users/sergo/Documents/WEB/WebLessons/News_Portal/venv/lib/python3.10/site-packages/django/template/base.py", line 175, in render
    return self._render(context)
  File "/Users/sergo/Documents/WEB/WebLessons/News_Portal/venv/lib/python3.10/site-packages/django/template/base.py", line 167, in _render
    return self.nodelist.render(context)
  File "/Users/sergo/Documents/WEB/WebLessons/News_Portal/venv/lib/python3.10/site-packages/django/template/base.py", line 1005, in render
    return SafeString("".join([node.render_annotated(context) for node in self]))
  File "/Users/sergo/Documents/WEB/WebLessons/News_Portal/venv/lib/python3.10/site-packages/django/template/base.py", line 1005, in <listcomp>
    return SafeString("".join([node.render_annotated(context) for node in self]))
  File "/Users/sergo/Documents/WEB/WebLessons/News_Portal/venv/lib/python3.10/site-packages/django/template/base.py", line 966, in render_annotated
    return self.render(context)
  File "/Users/sergo/Documents/WEB/WebLessons/News_Portal/venv/lib/python3.10/site-packages/django/template/loader_tags.py", line 157, in render
    return compiled_parent._render(context)
  File "/Users/sergo/Documents/WEB/WebLessons/News_Portal/venv/lib/python3.10/site-packages/django/template/base.py", line 167, in _render
    return self.nodelist.render(context)
  File "/Users/sergo/Documents/WEB/WebLessons/News_Portal/venv/lib/python3.10/site-packages/django/template/base.py", line 1005, in render
    return SafeString("".join([node.render_annotated(context) for node in self]))
  File "/Users/sergo/Documents/WEB/WebLessons/News_Portal/venv/lib/python3.10/site-packages/django/template/base.py", line 1005, in <listcomp>
    return SafeString("".join([node.render_annotated(context) for node in self]))
  File "/Users/sergo/Documents/WEB/WebLessons/News_Portal/venv/lib/python3.10/site-packages/django/template/base.py", line 966, in render_annotated
    return self.render(context)
  File "/Users/sergo/Documents/WEB/WebLessons/News_Portal/venv/lib/python3.10/site-packages/django/template/loader_tags.py", line 63, in render
    result = block.nodelist.render(context)
  File "/Users/sergo/Documents/WEB/WebLessons/News_Portal/venv/lib/python3.10/site-packages/django/template/base.py", line 1005, in render
    return SafeString("".join([node.render_annotated(context) for node in self]))
  File "/Users/sergo/Documents/WEB/WebLessons/News_Portal/venv/lib/python3.10/site-packages/django/template/base.py", line 1005, in <listcomp>
    return SafeString("".join([node.render_annotated(context) for node in self]))
  File "/Users/sergo/Documents/WEB/WebLessons/News_Portal/venv/lib/python3.10/site-packages/django/template/base.py", line 966, in render_annotated
    return self.render(context)
  File "/Users/sergo/Documents/WEB/WebLessons/News_Portal/venv/lib/python3.10/site-packages/django/template/base.py", line 1064, in render
    output = self.filter_expression.resolve(context)
  File "/Users/sergo/Documents/WEB/WebLessons/News_Portal/venv/lib/python3.10/site-packages/django/template/base.py", line 742, in resolve
    new_obj = func(obj, *arg_vals)
  File "/Users/sergo/Documents/WEB/WebLessons/News_Portal/NewsPortalProject/news/templatetags/custom_filters.py", line 19, in censor
    if c_word[-1] == ',' or c_word[-1] == '.':
IndexError: string index out of range
2022-09-11 10:48:28,052 ERROR "GET /news/105 HTTP/1.1" 500 145 /Users/sergo/Documents/WEB/WebLessons/News_Portal/venv/lib/python3.10/site-packages/django/core/servers/basehttp.py None
2022-09-11 13:57:26,972 ERROR Internal Server Error: /news/create/ /Users/sergo/Documents/WEB/WebLessons/News_Portal/venv/lib/python3.10/site-packages/django/utils/log.py (<class 'kombu.exceptions.OperationalError'>, OperationalError('Error 61 connecting to localhost:6379. Connection refused.'), <traceback object at 0x10f49bd40>)
Traceback (most recent call last):
  File "/Users/sergo/Documents/WEB/WebLessons/News_Portal/venv/lib/python3.10/site-packages/redis/connection.py", line 611, in connect
    sock = self.retry.call_with_retry(
  File "/Users/sergo/Documents/WEB/WebLessons/News_Portal/venv/lib/python3.10/site-packages/redis/retry.py", line 46, in call_with_retry
    return do()
  File "/Users/sergo/Documents/WEB/WebLessons/News_Portal/venv/lib/python3.10/site-packages/redis/connection.py", line 612, in <lambda>
    lambda: self._connect(), lambda error: self.disconnect(error)
  File "/Users/sergo/Documents/WEB/WebLessons/News_Portal/venv/lib/python3.10/site-packages/redis/connection.py", line 677, in _connect
    raise err
  File "/Users/sergo/Documents/WEB/WebLessons/News_Portal/venv/lib/python3.10/site-packages/redis/connection.py", line 665, in _connect
    sock.connect(socket_address)
ConnectionRefusedError: [Errno 61] Connection refused

During handling of the above exception, another exception occurred:

Traceback (most recent call last):
  File "/Users/sergo/Documents/WEB/WebLessons/News_Portal/venv/lib/python3.10/site-packages/celery/backends/redis.py", line 119, in reconnect_on_error
    yield
  File "/Users/sergo/Documents/WEB/WebLessons/News_Portal/venv/lib/python3.10/site-packages/celery/backends/redis.py", line 169, in _consume_from
    self._pubsub.subscribe(key)
  File "/Users/sergo/Documents/WEB/WebLessons/News_Portal/venv/lib/python3.10/site-packages/redis/client.py", line 1592, in subscribe
    ret_val = self.execute_command("SUBSCRIBE", *new_channels.keys())
  File "/Users/sergo/Documents/WEB/WebLessons/News_Portal/venv/lib/python3.10/site-packages/redis/client.py", line 1433, in execute_command
    self.connection = self.connection_pool.get_connection(
  File "/Users/sergo/Documents/WEB/WebLessons/News_Portal/venv/lib/python3.10/site-packages/redis/connection.py", line 1387, in get_connection
    connection.connect()
  File "/Users/sergo/Documents/WEB/WebLessons/News_Portal/venv/lib/python3.10/site-packages/redis/connection.py", line 617, in connect
    raise ConnectionError(self._error_message(e))
redis.exceptions.ConnectionError: Error 61 connecting to localhost:6379. Connection refused.

During handling of the above exception, another exception occurred:

Traceback (most recent call last):
  File "/Users/sergo/Documents/WEB/WebLessons/News_Portal/venv/lib/python3.10/site-packages/redis/connection.py", line 611, in connect
    sock = self.retry.call_with_retry(
  File "/Users/sergo/Documents/WEB/WebLessons/News_Portal/venv/lib/python3.10/site-packages/redis/retry.py", line 46, in call_with_retry
    return do()
  File "/Users/sergo/Documents/WEB/WebLessons/News_Portal/venv/lib/python3.10/site-packages/redis/connection.py", line 612, in <lambda>
    lambda: self._connect(), lambda error: self.disconnect(error)
  File "/Users/sergo/Documents/WEB/WebLessons/News_Portal/venv/lib/python3.10/site-packages/redis/connection.py", line 677, in _connect
    raise err
  File "/Users/sergo/Documents/WEB/WebLessons/News_Portal/venv/lib/python3.10/site-packages/redis/connection.py", line 665, in _connect
    sock.connect(socket_address)
ConnectionRefusedError: [Errno 61] Connection refused

During handling of the above exception, another exception occurred:

Traceback (most recent call last):
  File "/Users/sergo/Documents/WEB/WebLessons/News_Portal/venv/lib/python3.10/site-packages/kombu/connection.py", line 446, in _reraise_as_library_errors
    yield
  File "/Users/sergo/Documents/WEB/WebLessons/News_Portal/venv/lib/python3.10/site-packages/celery/app/base.py", line 787, in send_task
    self.backend.on_task_call(P, task_id)
  File "/Users/sergo/Documents/WEB/WebLessons/News_Portal/venv/lib/python3.10/site-packages/celery/backends/redis.py", line 365, in on_task_call
    self.result_consumer.consume_from(task_id)
  File "/Users/sergo/Documents/WEB/WebLessons/News_Portal/venv/lib/python3.10/site-packages/celery/backends/redis.py", line 161, in consume_from
    return self.start(task_id)
  File "/Users/sergo/Documents/WEB/WebLessons/News_Portal/venv/lib/python3.10/site-packages/celery/backends/redis.py", line 139, in start
    self._consume_from(initial_task_id)
  File "/Users/sergo/Documents/WEB/WebLessons/News_Portal/venv/lib/python3.10/site-packages/celery/backends/redis.py", line 168, in _consume_from
    with self.reconnect_on_error():
  File "/Library/Frameworks/Python.framework/Versions/3.10/lib/python3.10/contextlib.py", line 153, in __exit__
    self.gen.throw(typ, value, traceback)
  File "/Users/sergo/Documents/WEB/WebLessons/News_Portal/venv/lib/python3.10/site-packages/celery/backends/redis.py", line 122, in reconnect_on_error
    self._ensure(self._reconnect_pubsub, ())
  File "/Users/sergo/Documents/WEB/WebLessons/News_Portal/venv/lib/python3.10/site-packages/celery/backends/redis.py", line 376, in ensure
    return retry_over_time(
  File "/Users/sergo/Documents/WEB/WebLessons/News_Portal/venv/lib/python3.10/site-packages/kombu/utils/functional.py", line 312, in retry_over_time
    return fun(*args, **kwargs)
  File "/Users/sergo/Documents/WEB/WebLessons/News_Portal/venv/lib/python3.10/site-packages/celery/backends/redis.py", line 106, in _reconnect_pubsub
    metas = self.backend.client.mget(self.subscribed_to)
  File "/Users/sergo/Documents/WEB/WebLessons/News_Portal/venv/lib/python3.10/site-packages/redis/commands/core.py", line 1893, in mget
    return self.execute_command("MGET", *args, **options)
  File "/Users/sergo/Documents/WEB/WebLessons/News_Portal/venv/lib/python3.10/site-packages/redis/client.py", line 1235, in execute_command
    conn = self.connection or pool.get_connection(command_name, **options)
  File "/Users/sergo/Documents/WEB/WebLessons/News_Portal/venv/lib/python3.10/site-packages/redis/connection.py", line 1387, in get_connection
    connection.connect()
  File "/Users/sergo/Documents/WEB/WebLessons/News_Portal/venv/lib/python3.10/site-packages/redis/connection.py", line 617, in connect
    raise ConnectionError(self._error_message(e))
redis.exceptions.ConnectionError: Error 61 connecting to localhost:6379. Connection refused.

The above exception was the direct cause of the following exception:

Traceback (most recent call last):
  File "/Users/sergo/Documents/WEB/WebLessons/News_Portal/venv/lib/python3.10/site-packages/django/core/handlers/exception.py", line 55, in inner
    response = get_response(request)
  File "/Users/sergo/Documents/WEB/WebLessons/News_Portal/venv/lib/python3.10/site-packages/django/core/handlers/base.py", line 197, in _get_response
    response = wrapped_callback(request, *callback_args, **callback_kwargs)
  File "/Users/sergo/Documents/WEB/WebLessons/News_Portal/venv/lib/python3.10/site-packages/django/views/generic/base.py", line 103, in view
    return self.dispatch(request, *args, **kwargs)
  File "/Users/sergo/Documents/WEB/WebLessons/News_Portal/venv/lib/python3.10/site-packages/django/contrib/auth/mixins.py", line 73, in dispatch
    return super().dispatch(request, *args, **kwargs)
  File "/Users/sergo/Documents/WEB/WebLessons/News_Portal/venv/lib/python3.10/site-packages/django/contrib/auth/mixins.py", line 109, in dispatch
    return super().dispatch(request, *args, **kwargs)
  File "/Users/sergo/Documents/WEB/WebLessons/News_Portal/venv/lib/python3.10/site-packages/django/views/generic/base.py", line 142, in dispatch
    return handler(request, *args, **kwargs)
  File "/Users/sergo/Documents/WEB/WebLessons/News_Portal/venv/lib/python3.10/site-packages/django/views/generic/edit.py", line 184, in post
    return super().post(request, *args, **kwargs)
  File "/Users/sergo/Documents/WEB/WebLessons/News_Portal/venv/lib/python3.10/site-packages/django/views/generic/edit.py", line 153, in post
    return self.form_valid(form)
  File "/Users/sergo/Documents/WEB/WebLessons/News_Portal/NewsPortalProject/news/views.py", line 142, in form_valid
    new_post_notify.delay()
  File "/Users/sergo/Documents/WEB/WebLessons/News_Portal/venv/lib/python3.10/site-packages/celery/app/task.py", line 425, in delay
    return self.apply_async(args, kwargs)
  File "/Users/sergo/Documents/WEB/WebLessons/News_Portal/venv/lib/python3.10/site-packages/celery/app/task.py", line 575, in apply_async
    return app.send_task(
  File "/Users/sergo/Documents/WEB/WebLessons/News_Portal/venv/lib/python3.10/site-packages/celery/app/base.py", line 785, in send_task
    with P.connection._reraise_as_library_errors():
  File "/Library/Frameworks/Python.framework/Versions/3.10/lib/python3.10/contextlib.py", line 153, in __exit__
    self.gen.throw(typ, value, traceback)
  File "/Users/sergo/Documents/WEB/WebLessons/News_Portal/venv/lib/python3.10/site-packages/kombu/connection.py", line 450, in _reraise_as_library_errors
    raise ConnectionError(str(exc)) from exc
kombu.exceptions.OperationalError: Error 61 connecting to localhost:6379. Connection refused.
2022-09-11 13:57:26,976 ERROR "POST /news/create/ HTTP/1.1" 500 270455 /Users/sergo/Documents/WEB/WebLessons/News_Portal/venv/lib/python3.10/site-packages/django/core/servers/basehttp.py None
2022-09-11 15:03:02,042 ERROR Internal Server Error: / /Users/sergo/Documents/WEB/WebLessons/News_Portal/venv/lib/python3.10/site-packages/django/utils/log.py (<class 'django.template.exceptions.TemplateSyntaxError'>, TemplateSyntaxError("Invalid block tag on line 4: 'trans', expected 'endblock'. Did you forget to register or load this tag?"), <traceback object at 0x1105e3540>)
Traceback (most recent call last):
  File "/Users/sergo/Documents/WEB/WebLessons/News_Portal/venv/lib/python3.10/site-packages/django/template/base.py", line 505, in parse
    compile_func = self.tags[command]
KeyError: 'trans'

During handling of the above exception, another exception occurred:

Traceback (most recent call last):
  File "/Users/sergo/Documents/WEB/WebLessons/News_Portal/venv/lib/python3.10/site-packages/django/core/handlers/exception.py", line 55, in inner
    response = get_response(request)
  File "/Users/sergo/Documents/WEB/WebLessons/News_Portal/venv/lib/python3.10/site-packages/django/core/handlers/base.py", line 220, in _get_response
    response = response.render()
  File "/Users/sergo/Documents/WEB/WebLessons/News_Portal/venv/lib/python3.10/site-packages/django/template/response.py", line 114, in render
    self.content = self.rendered_content
  File "/Users/sergo/Documents/WEB/WebLessons/News_Portal/venv/lib/python3.10/site-packages/django/template/response.py", line 90, in rendered_content
    template = self.resolve_template(self.template_name)
  File "/Users/sergo/Documents/WEB/WebLessons/News_Portal/venv/lib/python3.10/site-packages/django/template/response.py", line 72, in resolve_template
    return select_template(template, using=self.using)
  File "/Users/sergo/Documents/WEB/WebLessons/News_Portal/venv/lib/python3.10/site-packages/django/template/loader.py", line 42, in select_template
    return engine.get_template(template_name)
  File "/Users/sergo/Documents/WEB/WebLessons/News_Portal/venv/lib/python3.10/site-packages/django/template/backends/django.py", line 34, in get_template
    return Template(self.engine.get_template(template_name), self)
  File "/Users/sergo/Documents/WEB/WebLessons/News_Portal/venv/lib/python3.10/site-packages/django/template/engine.py", line 175, in get_template
    template, origin = self.find_template(template_name)
  File "/Users/sergo/Documents/WEB/WebLessons/News_Portal/venv/lib/python3.10/site-packages/django/template/engine.py", line 157, in find_template
    template = loader.get_template(name, skip=skip)
  File "/Users/sergo/Documents/WEB/WebLessons/News_Portal/venv/lib/python3.10/site-packages/django/template/loaders/cached.py", line 57, in get_template
    template = super().get_template(template_name, skip)
  File "/Users/sergo/Documents/WEB/WebLessons/News_Portal/venv/lib/python3.10/site-packages/django/template/loaders/base.py", line 28, in get_template
    return Template(
  File "/Users/sergo/Documents/WEB/WebLessons/News_Portal/venv/lib/python3.10/site-packages/django/template/base.py", line 154, in __init__
    self.nodelist = self.compile_nodelist()
  File "/Users/sergo/Documents/WEB/WebLessons/News_Portal/venv/lib/python3.10/site-packages/django/template/base.py", line 200, in compile_nodelist
    return parser.parse()
  File "/Users/sergo/Documents/WEB/WebLessons/News_Portal/venv/lib/python3.10/site-packages/django/template/base.py", line 513, in parse
    raise self.error(token, e)
  File "/Users/sergo/Documents/WEB/WebLessons/News_Portal/venv/lib/python3.10/site-packages/django/template/base.py", line 511, in parse
    compiled_result = compile_func(self, token)
  File "/Users/sergo/Documents/WEB/WebLessons/News_Portal/venv/lib/python3.10/site-packages/django/template/loader_tags.py", line 293, in do_extends
    nodelist = parser.parse()
  File "/Users/sergo/Documents/WEB/WebLessons/News_Portal/venv/lib/python3.10/site-packages/django/template/base.py", line 513, in parse
    raise self.error(token, e)
  File "/Users/sergo/Documents/WEB/WebLessons/News_Portal/venv/lib/python3.10/site-packages/django/template/base.py", line 511, in parse
    compiled_result = compile_func(self, token)
  File "/Users/sergo/Documents/WEB/WebLessons/News_Portal/venv/lib/python3.10/site-packages/django/template/loader_tags.py", line 232, in do_block
    nodelist = parser.parse(("endblock",))
  File "/Users/sergo/Documents/WEB/WebLessons/News_Portal/venv/lib/python3.10/site-packages/django/template/base.py", line 507, in parse
    self.invalid_block_tag(token, command, parse_until)
  File "/Users/sergo/Documents/WEB/WebLessons/News_Portal/venv/lib/python3.10/site-packages/django/template/base.py", line 558, in invalid_block_tag
    raise self.error(
django.template.exceptions.TemplateSyntaxError: Invalid block tag on line 4: 'trans', expected 'endblock'. Did you forget to register or load this tag?
2022-09-11 15:03:02,044 ERROR "GET / HTTP/1.1" 500 196496 /Users/sergo/Documents/WEB/WebLessons/News_Portal/venv/lib/python3.10/site-packages/django/core/servers/basehttp.py None
